2024-04-20T07:41:35 {"cpu": 0.18408203125, "cpu_total": 16, "cpu_usage": 0.011505126953125, "memory": 2766.0, "memory_total": 9830.0, "memory_usage": 0.281383519837233, "pipeline_run_id": 32, "pipeline_schedule_id": 2, "pipeline_uuid": "etl_gcs_green_data", "hostname": "54ba8a1e31e8", "level": "INFO", "message": "Pipeline etl_gcs_green_data for run 32 in schedule 2 is alive.", "timestamp": 1713598895.629595, "uuid": "0233d2945fb64bd185db92ac6dc40ff9"}
2024-04-20T07:41:35 {"block_run_id": 100, "block_uuid": "load_api_green_taxi", "pipeline_run_id": 32, "pipeline_schedule_id": 2, "pipeline_uuid": "etl_gcs_green_data", "hostname": "54ba8a1e31e8", "level": "INFO", "message": "Execute PipelineRun 32, BlockRun 100: pipeline etl_gcs_green_data block load_api_green_taxi", "timestamp": 1713598895.904114, "uuid": "ba27fdc074dc45b0bf389fa57c7c436e"}
2024-04-20T07:41:35 {"cpu": 0.18408203125, "cpu_total": 16, "cpu_usage": 0.011505126953125, "memory": 2803.0, "memory_total": 9830.0, "memory_usage": 0.285147507629705, "pipeline_run_id": 32, "pipeline_schedule_id": 2, "pipeline_uuid": "etl_gcs_green_data", "hostname": "54ba8a1e31e8", "level": "INFO", "message": "Pipeline etl_gcs_green_data for run 32 in schedule 2 is alive.", "timestamp": 1713598895.925296, "uuid": "563a1b7f590d4bc186d4e1bdd1d5722f"}
2024-04-20T07:41:36 {"block_run_id": 100, "block_uuid": "load_api_green_taxi", "pipeline_run_id": 32, "pipeline_schedule_id": 2, "pipeline_uuid": "etl_gcs_green_data", "hostname": "54ba8a1e31e8", "level": "INFO", "message": "BlockRun 100 (block_uuid: load_api_green_taxi) completes.", "timestamp": 1713598896.888601, "uuid": "fbd9ed7e9903459fa5d0334a2a770062"}
2024-04-20T07:41:45 {"cpu": 0.18701171875, "cpu_total": 16, "cpu_usage": 0.011688232421875, "memory": 2758.0, "memory_total": 9830.0, "memory_usage": 0.2805696846388606, "pipeline_run_id": 32, "pipeline_schedule_id": 2, "pipeline_uuid": "etl_gcs_green_data", "hostname": "54ba8a1e31e8", "level": "INFO", "message": "Pipeline etl_gcs_green_data for run 32 in schedule 2 is alive.", "timestamp": 1713598905.36171, "uuid": "b71d880b792d48b59c89475b3960bc1c"}
2024-04-20T07:41:45 {"block_run_id": 101, "block_uuid": "transform_taxi_data", "pipeline_run_id": 32, "pipeline_schedule_id": 2, "pipeline_uuid": "etl_gcs_green_data", "hostname": "54ba8a1e31e8", "level": "INFO", "message": "Execute PipelineRun 32, BlockRun 101: pipeline etl_gcs_green_data block transform_taxi_data", "timestamp": 1713598905.644094, "uuid": "127452bb061249378e084c9a0acef4d6"}
2024-04-20T07:41:47 {"block_run_id": 101, "block_uuid": "transform_taxi_data", "pipeline_run_id": 32, "pipeline_schedule_id": 2, "pipeline_uuid": "etl_gcs_green_data", "hostname": "54ba8a1e31e8", "level": "EXCEPTION", "message": "BlockRun 101 (block_uuid: transform_taxi_data) failed.", "timestamp": 1713598907.019061, "uuid": "22af20b30edd4c29b6aa18e37b7e001b", "error": ["Traceback (most recent call last):\n  File \"/usr/local/lib/python3.10/site-packages/mage_ai/data_preparation/executors/block_executor.py\", line 613, in execute\n    result = __execute_with_retry()\n  File \"/usr/local/lib/python3.10/site-packages/mage_ai/shared/retry.py\", line 54, in retry_func\n    raise e\n  File \"/usr/local/lib/python3.10/site-packages/mage_ai/shared/retry.py\", line 38, in retry_func\n    return func(*args, **kwargs)\n  File \"/usr/local/lib/python3.10/site-packages/mage_ai/data_preparation/executors/block_executor.py\", line 588, in __execute_with_retry\n    return self._execute(\n  File \"/usr/local/lib/python3.10/site-packages/mage_ai/data_preparation/executors/block_executor.py\", line 1107, in _execute\n    self.block.run_tests(\n  File \"/usr/local/lib/python3.10/site-packages/mage_ai/data_preparation/models/block/__init__.py\", line 2842, in run_tests\n    raise Exception(f'Failed to pass tests for block {self.uuid}')\nException: Failed to pass tests for block transform_taxi_data\n"], "error_stack": [["  File \"/usr/local/bin/mage\", line 8, in <module>\n    sys.exit(app())\n", "  File \"/usr/local/lib/python3.10/site-packages/typer/main.py\", line 311, in __call__\n    return get_command(self)(*args, **kwargs)\n", "  File \"/usr/local/lib/python3.10/site-packages/click/core.py\", line 1130, in __call__\n    return self.main(*args, **kwargs)\n", "  File \"/usr/local/lib/python3.10/site-packages/typer/core.py\", line 778, in main\n    return _main(\n", "  File \"/usr/local/lib/python3.10/site-packages/typer/core.py\", line 216, in _main\n    rv = self.invoke(ctx)\n", "  File \"/usr/local/lib/python3.10/site-packages/click/core.py\", line 1657, in invoke\n    return _process_result(sub_ctx.command.invoke(sub_ctx))\n", "  File \"/usr/local/lib/python3.10/site-packages/click/core.py\", line 1404, in invoke\n    return ctx.invoke(self.callback, **ctx.params)\n", "  File \"/usr/local/lib/python3.10/site-packages/click/core.py\", line 760, in invoke\n    return __callback(*args, **kwargs)\n", "  File \"/usr/local/lib/python3.10/site-packages/typer/main.py\", line 683, in wrapper\n    return callback(**use_params)  # type: ignore\n", "  File \"/usr/local/lib/python3.10/site-packages/mage_ai/cli/main.py\", line 163, in start\n    start_server(\n", "  File \"/usr/local/lib/python3.10/site-packages/mage_ai/server/server.py\", line 750, in start_server\n    scheduler_manager.start_scheduler()\n", "  File \"/usr/local/lib/python3.10/site-packages/mage_ai/server/scheduler_manager.py\", line 92, in start_scheduler\n    proc.start()\n", "  File \"/usr/local/lib/python3.10/multiprocessing/process.py\", line 121, in start\n    self._popen = self._Popen(self)\n", "  File \"/usr/local/lib/python3.10/multiprocessing/context.py\", line 224, in _Popen\n    return _default_context.get_context().Process._Popen(process_obj)\n", "  File \"/usr/local/lib/python3.10/multiprocessing/context.py\", line 281, in _Popen\n    return Popen(process_obj)\n", "  File \"/usr/local/lib/python3.10/multiprocessing/popen_fork.py\", line 19, in __init__\n    self._launch(process_obj)\n", "  File \"/usr/local/lib/python3.10/multiprocessing/popen_fork.py\", line 71, in _launch\n    code = process_obj._bootstrap(parent_sentinel=child_r)\n", "  File \"/usr/local/lib/python3.10/multiprocessing/process.py\", line 314, in _bootstrap\n    self.run()\n", "  File \"/usr/local/lib/python3.10/multiprocessing/process.py\", line 108, in run\n    self._target(*self._args, **self._kwargs)\n", "  File \"/usr/local/lib/python3.10/site-packages/mage_ai/orchestration/db/process.py\", line 15, in start_session_and_run\n    results = target(*args)\n", "  File \"/usr/local/lib/python3.10/site-packages/mage_ai/server/scheduler_manager.py\", line 53, in run_scheduler\n    LoopTimeTrigger().start()\n", "  File \"/usr/local/lib/python3.10/site-packages/mage_ai/orchestration/triggers/loop_time_trigger.py\", line 14, in start\n    self.run()\n", "  File \"/usr/local/lib/python3.10/site-packages/mage_ai/orchestration/triggers/time_trigger.py\", line 11, in run\n    schedule_all()\n", "  File \"/usr/local/lib/python3.10/site-packages/mage_ai/orchestration/pipeline_scheduler_original.py\", line 1654, in schedule_all\n    PipelineScheduler(r).schedule()\n", "  File \"/usr/local/lib/python3.10/site-packages/mage_ai/orchestration/db/__init__.py\", line 157, in func_with_rollback\n    return func(*args, **kwargs)\n", "  File \"/usr/local/lib/python3.10/site-packages/mage_ai/orchestration/pipeline_scheduler_original.py\", line 318, in schedule\n    self.__schedule_blocks(block_runs)\n", "  File \"/usr/local/lib/python3.10/site-packages/mage_ai/orchestration/pipeline_scheduler_original.py\", line 611, in __schedule_blocks\n    job_manager.add_job(\n", "  File \"/usr/local/lib/python3.10/site-packages/mage_ai/orchestration/job_manager.py\", line 28, in add_job\n    self.queue.enqueue(job_id, target, *args, **kwargs)\n", "  File \"/usr/local/lib/python3.10/site-packages/mage_ai/orchestration/queue/process_queue.py\", line 121, in enqueue\n    self.start_worker_pool()\n", "  File \"/usr/local/lib/python3.10/site-packages/mage_ai/orchestration/queue/process_queue.py\", line 198, in start_worker_pool\n    self.worker_pool_proc.start()\n", "  File \"/usr/local/lib/python3.10/multiprocessing/process.py\", line 121, in start\n    self._popen = self._Popen(self)\n", "  File \"/usr/local/lib/python3.10/multiprocessing/context.py\", line 224, in _Popen\n    return _default_context.get_context().Process._Popen(process_obj)\n", "  File \"/usr/local/lib/python3.10/multiprocessing/context.py\", line 281, in _Popen\n    return Popen(process_obj)\n", "  File \"/usr/local/lib/python3.10/multiprocessing/popen_fork.py\", line 19, in __init__\n    self._launch(process_obj)\n", "  File \"/usr/local/lib/python3.10/multiprocessing/popen_fork.py\", line 71, in _launch\n    code = process_obj._bootstrap(parent_sentinel=child_r)\n", "  File \"/usr/local/lib/python3.10/multiprocessing/process.py\", line 314, in _bootstrap\n    self.run()\n", "  File \"/usr/local/lib/python3.10/multiprocessing/process.py\", line 108, in run\n    self._target(*self._args, **self._kwargs)\n", "  File \"/usr/local/lib/python3.10/site-packages/mage_ai/orchestration/queue/process_queue.py\", line 351, in poll_job_and_execute\n    worker.start()\n", "  File \"/usr/local/lib/python3.10/multiprocessing/process.py\", line 121, in start\n    self._popen = self._Popen(self)\n", "  File \"/usr/local/lib/python3.10/multiprocessing/context.py\", line 224, in _Popen\n    return _default_context.get_context().Process._Popen(process_obj)\n", "  File \"/usr/local/lib/python3.10/multiprocessing/context.py\", line 281, in _Popen\n    return Popen(process_obj)\n", "  File \"/usr/local/lib/python3.10/multiprocessing/popen_fork.py\", line 19, in __init__\n    self._launch(process_obj)\n", "  File \"/usr/local/lib/python3.10/multiprocessing/popen_fork.py\", line 71, in _launch\n    code = process_obj._bootstrap(parent_sentinel=child_r)\n", "  File \"/usr/local/lib/python3.10/multiprocessing/process.py\", line 314, in _bootstrap\n    self.run()\n", "  File \"/usr/local/lib/python3.10/site-packages/newrelic/api/background_task.py\", line 117, in wrapper\n    return wrapped(*args, **kwargs)\n", "  File \"/usr/local/lib/python3.10/site-packages/mage_ai/orchestration/queue/process_queue.py\", line 315, in run\n    start_session_and_run(args[1], *args[2], **args[3])\n", "  File \"/usr/local/lib/python3.10/site-packages/mage_ai/orchestration/db/process.py\", line 15, in start_session_and_run\n    results = target(*args)\n", "  File \"/usr/local/lib/python3.10/site-packages/mage_ai/orchestration/pipeline_scheduler_original.py\", line 1163, in run_block\n    return ExecutorFactory.get_block_executor(\n", "  File \"/usr/local/lib/python3.10/site-packages/mage_ai/data_preparation/executors/block_executor.py\", line 641, in execute\n    on_failure(\n", "  File \"/usr/local/lib/python3.10/site-packages/mage_ai/orchestration/db/__init__.py\", line 157, in func_with_rollback\n    return func(*args, **kwargs)\n", "  File \"/usr/local/lib/python3.10/site-packages/mage_ai/orchestration/pipeline_scheduler_original.py\", line 442, in on_block_failure\n    self.logger.exception(\n", "  File \"/usr/local/lib/python3.10/site-packages/mage_ai/data_preparation/logging/logger.py\", line 30, in exception\n    self.__send_message('exception', message, **kwargs)\n", "  File \"/usr/local/lib/python3.10/site-packages/mage_ai/data_preparation/logging/logger.py\", line 65, in __send_message\n    data['error_stack'] = traceback.format_stack(),\n"]], "error_stacktrace": ["Failed to pass tests for block transform_taxi_data"]}
Traceback (most recent call last):
  File "/usr/local/lib/python3.10/site-packages/mage_ai/data_preparation/executors/block_executor.py", line 613, in execute
    result = __execute_with_retry()
  File "/usr/local/lib/python3.10/site-packages/mage_ai/shared/retry.py", line 54, in retry_func
    raise e
  File "/usr/local/lib/python3.10/site-packages/mage_ai/shared/retry.py", line 38, in retry_func
    return func(*args, **kwargs)
  File "/usr/local/lib/python3.10/site-packages/mage_ai/data_preparation/executors/block_executor.py", line 588, in __execute_with_retry
    return self._execute(
  File "/usr/local/lib/python3.10/site-packages/mage_ai/data_preparation/executors/block_executor.py", line 1107, in _execute
    self.block.run_tests(
  File "/usr/local/lib/python3.10/site-packages/mage_ai/data_preparation/models/block/__init__.py", line 2842, in run_tests
    raise Exception(f'Failed to pass tests for block {self.uuid}')
Exception: Failed to pass tests for block transform_taxi_data
2024-04-20T07:41:55 {"cpu": 0.18994140625, "cpu_total": 16, "cpu_usage": 0.011871337890625, "memory": 2759.0, "memory_total": 9830.0, "memory_usage": 0.2806714140386572, "pipeline_run_id": 32, "pipeline_schedule_id": 2, "pipeline_uuid": "etl_gcs_green_data", "hostname": "54ba8a1e31e8", "level": "INFO", "message": "Pipeline etl_gcs_green_data for run 32 in schedule 2 is alive.", "timestamp": 1713598915.795181, "uuid": "354a712b73e740d2a242323c3d35559a"}
