2024-04-20T07:30:58 {"block_run_id": 47, "block_uuid": "transform_taxi_data", "pipeline_run_id": 14, "pipeline_schedule_id": 2, "pipeline_uuid": "etl_gcs_green_data", "hostname": "54ba8a1e31e8", "block_type": "transformer", "level": "INFO", "message": "Start executing block with BlockExecutor.", "timestamp": 1713598258.309394, "uuid": "1117b858552b41ccbc3b2e361095bb8c"}
2024-04-20T07:30:58 {"block_run_id": 47, "block_uuid": "transform_taxi_data", "pipeline_run_id": 14, "pipeline_schedule_id": 2, "pipeline_uuid": "etl_gcs_green_data", "hostname": "54ba8a1e31e8", "block_type": "transformer", "level": "INFO", "message": "Preprocessing: rows with zero passengers 161", "timestamp": 1713598258.538977, "uuid": "36775ddb4fb04634b05aa56860016438"}
2024-04-20T07:30:59 {"block_run_id": 47, "block_uuid": "transform_taxi_data", "pipeline_run_id": 14, "pipeline_schedule_id": 2, "pipeline_uuid": "etl_gcs_green_data", "hostname": "54ba8a1e31e8", "block_type": "transformer", "level": "INFO", "message": "--------------------------------------------------------------", "timestamp": 1713598259.068883, "uuid": "47af9e60ebe24517bbafc030350588d8"}
2024-04-20T07:30:59 {"block_run_id": 47, "block_uuid": "transform_taxi_data", "pipeline_run_id": 14, "pipeline_schedule_id": 2, "pipeline_uuid": "etl_gcs_green_data", "hostname": "54ba8a1e31e8", "block_type": "transformer", "level": "INFO", "message": "1/1 tests passed.", "timestamp": 1713598259.07008, "uuid": "a8fc8148bfa64441b38ab9d7460cd51d"}
2024-04-20T07:30:59 {"block_run_id": 47, "block_uuid": "transform_taxi_data", "pipeline_run_id": 14, "pipeline_schedule_id": 2, "pipeline_uuid": "etl_gcs_green_data", "hostname": "54ba8a1e31e8", "block_type": "transformer", "level": "INFO", "message": "Finish executing block with BlockExecutor.", "timestamp": 1713598259.072319, "uuid": "998d2563457d4b95934ecef385f94ee5"}
2024-04-20T07:41:11 {"block_run_id": 86, "block_uuid": "transform_taxi_data", "pipeline_run_id": 27, "pipeline_schedule_id": 2, "pipeline_uuid": "etl_gcs_green_data", "hostname": "54ba8a1e31e8", "block_type": "transformer", "level": "INFO", "message": "Start executing block with BlockExecutor.", "timestamp": 1713598871.71773, "uuid": "33eb36e6f77a46a3a4c63ffe29538630"}
2024-04-20T07:41:11 {"block_run_id": 86, "block_uuid": "transform_taxi_data", "pipeline_run_id": 27, "pipeline_schedule_id": 2, "pipeline_uuid": "etl_gcs_green_data", "hostname": "54ba8a1e31e8", "block_type": "transformer", "level": "INFO", "message": "Preprocessing: rows with zero passengers 161", "timestamp": 1713598871.998932, "uuid": "b952d340dc524e6689e385e00b4c59be"}
2024-04-20T07:41:12 {"block_run_id": 86, "block_uuid": "transform_taxi_data", "pipeline_run_id": 27, "pipeline_schedule_id": 2, "pipeline_uuid": "etl_gcs_green_data", "hostname": "54ba8a1e31e8", "block_type": "transformer", "level": "INFO", "message": "==============================================================", "timestamp": 1713598872.683841, "uuid": "4d4b609320c14929a8f3d2ac38c23ad4"}
2024-04-20T07:41:12 {"block_run_id": 86, "block_uuid": "transform_taxi_data", "pipeline_run_id": 27, "pipeline_schedule_id": 2, "pipeline_uuid": "etl_gcs_green_data", "hostname": "54ba8a1e31e8", "block_type": "transformer", "level": "INFO", "message": "FAIL: test_output (block: transform_taxi_data)", "timestamp": 1713598872.686096, "uuid": "de15f893729240e491fed79c5da335f9"}
2024-04-20T07:41:12 {"block_run_id": 86, "block_uuid": "transform_taxi_data", "pipeline_run_id": 27, "pipeline_schedule_id": 2, "pipeline_uuid": "etl_gcs_green_data", "hostname": "54ba8a1e31e8", "block_type": "transformer", "level": "INFO", "message": "--------------------------------------------------------------", "timestamp": 1713598872.687829, "uuid": "2e5fb84195a74f96be2d07c895c06477"}
2024-04-20T07:41:12 {"block_run_id": 86, "block_uuid": "transform_taxi_data", "pipeline_run_id": 27, "pipeline_schedule_id": 2, "pipeline_uuid": "etl_gcs_green_data", "hostname": "54ba8a1e31e8", "block_type": "transformer", "level": "INFO", "message": "Traceback (most recent call last):", "timestamp": 1713598872.689673, "uuid": "f54f86efedd24bf79b0e35bafcfea9d2"}
2024-04-20T07:41:12 {"block_run_id": 86, "block_uuid": "transform_taxi_data", "pipeline_run_id": 27, "pipeline_schedule_id": 2, "pipeline_uuid": "etl_gcs_green_data", "hostname": "54ba8a1e31e8", "block_type": "transformer", "level": "INFO", "message": "  File \"/usr/local/lib/python3.10/site-packages/mage_ai/data_preparation/models/block/__init__.py\", line 2811, in run_tests", "timestamp": 1713598872.691579, "uuid": "f22dcda9603b49d48ea5c322777570ce"}
2024-04-20T07:41:12 {"block_run_id": 86, "block_uuid": "transform_taxi_data", "pipeline_run_id": 27, "pipeline_schedule_id": 2, "pipeline_uuid": "etl_gcs_green_data", "hostname": "54ba8a1e31e8", "block_type": "transformer", "level": "INFO", "message": "    test_function(*outputs)", "timestamp": 1713598872.694107, "uuid": "0c8864b6893f479da4379a98e3b083f4"}
2024-04-20T07:41:12 {"block_run_id": 86, "block_uuid": "transform_taxi_data", "pipeline_run_id": 27, "pipeline_schedule_id": 2, "pipeline_uuid": "etl_gcs_green_data", "hostname": "54ba8a1e31e8", "block_type": "transformer", "level": "INFO", "message": "  File \"<string>\", line 33, in test_output", "timestamp": 1713598872.696192, "uuid": "a36447f8c4d949738782412820b72645"}
2024-04-20T07:41:12 {"block_run_id": 86, "block_uuid": "transform_taxi_data", "pipeline_run_id": 27, "pipeline_schedule_id": 2, "pipeline_uuid": "etl_gcs_green_data", "hostname": "54ba8a1e31e8", "block_type": "transformer", "level": "INFO", "message": "AssertionError: There are rides with zero", "timestamp": 1713598872.698029, "uuid": "de5224d888ad49a28a79b3532d9312d2"}
2024-04-20T07:41:12 {"block_run_id": 86, "block_uuid": "transform_taxi_data", "pipeline_run_id": 27, "pipeline_schedule_id": 2, "pipeline_uuid": "etl_gcs_green_data", "hostname": "54ba8a1e31e8", "block_type": "transformer", "level": "INFO", "message": "--------------------------------------------------------------", "timestamp": 1713598872.700359, "uuid": "d7a00c9778544e3a888a6372a03e33c5"}
2024-04-20T07:41:12 {"block_run_id": 86, "block_uuid": "transform_taxi_data", "pipeline_run_id": 27, "pipeline_schedule_id": 2, "pipeline_uuid": "etl_gcs_green_data", "hostname": "54ba8a1e31e8", "block_type": "transformer", "level": "INFO", "message": "0/1 tests passed.", "timestamp": 1713598872.702188, "uuid": "947f916c94604cb985241d36427c1e57"}
2024-04-20T07:41:12 {"block_run_id": 86, "block_uuid": "transform_taxi_data", "pipeline_run_id": 27, "pipeline_schedule_id": 2, "pipeline_uuid": "etl_gcs_green_data", "hostname": "54ba8a1e31e8", "block_type": "transformer", "level": "WARNING", "message": "Exception thrown when attempting to run <function BlockExecutor.execute.<locals>.__execute_with_retry at 0x7fd34ebb6200>, attempt 1 of 1", "timestamp": 1713598872.704611, "uuid": "234706d2a7934f838fa70d5fdec84d4f", "error": ["Traceback (most recent call last):\n  File \"/usr/local/lib/python3.10/site-packages/mage_ai/shared/retry.py\", line 38, in retry_func\n    return func(*args, **kwargs)\n  File \"/usr/local/lib/python3.10/site-packages/mage_ai/data_preparation/executors/block_executor.py\", line 588, in __execute_with_retry\n    return self._execute(\n  File \"/usr/local/lib/python3.10/site-packages/mage_ai/data_preparation/executors/block_executor.py\", line 1107, in _execute\n    self.block.run_tests(\n  File \"/usr/local/lib/python3.10/site-packages/mage_ai/data_preparation/models/block/__init__.py\", line 2842, in run_tests\n    raise Exception(f'Failed to pass tests for block {self.uuid}')\nException: Failed to pass tests for block transform_taxi_data\n"], "error_stack": [["  File \"/usr/local/bin/mage\", line 8, in <module>\n    sys.exit(app())\n", "  File \"/usr/local/lib/python3.10/site-packages/typer/main.py\", line 311, in __call__\n    return get_command(self)(*args, **kwargs)\n", "  File \"/usr/local/lib/python3.10/site-packages/click/core.py\", line 1130, in __call__\n    return self.main(*args, **kwargs)\n", "  File \"/usr/local/lib/python3.10/site-packages/typer/core.py\", line 778, in main\n    return _main(\n", "  File \"/usr/local/lib/python3.10/site-packages/typer/core.py\", line 216, in _main\n    rv = self.invoke(ctx)\n", "  File \"/usr/local/lib/python3.10/site-packages/click/core.py\", line 1657, in invoke\n    return _process_result(sub_ctx.command.invoke(sub_ctx))\n", "  File \"/usr/local/lib/python3.10/site-packages/click/core.py\", line 1404, in invoke\n    return ctx.invoke(self.callback, **ctx.params)\n", "  File \"/usr/local/lib/python3.10/site-packages/click/core.py\", line 760, in invoke\n    return __callback(*args, **kwargs)\n", "  File \"/usr/local/lib/python3.10/site-packages/typer/main.py\", line 683, in wrapper\n    return callback(**use_params)  # type: ignore\n", "  File \"/usr/local/lib/python3.10/site-packages/mage_ai/cli/main.py\", line 163, in start\n    start_server(\n", "  File \"/usr/local/lib/python3.10/site-packages/mage_ai/server/server.py\", line 750, in start_server\n    scheduler_manager.start_scheduler()\n", "  File \"/usr/local/lib/python3.10/site-packages/mage_ai/server/scheduler_manager.py\", line 92, in start_scheduler\n    proc.start()\n", "  File \"/usr/local/lib/python3.10/multiprocessing/process.py\", line 121, in start\n    self._popen = self._Popen(self)\n", "  File \"/usr/local/lib/python3.10/multiprocessing/context.py\", line 224, in _Popen\n    return _default_context.get_context().Process._Popen(process_obj)\n", "  File \"/usr/local/lib/python3.10/multiprocessing/context.py\", line 281, in _Popen\n    return Popen(process_obj)\n", "  File \"/usr/local/lib/python3.10/multiprocessing/popen_fork.py\", line 19, in __init__\n    self._launch(process_obj)\n", "  File \"/usr/local/lib/python3.10/multiprocessing/popen_fork.py\", line 71, in _launch\n    code = process_obj._bootstrap(parent_sentinel=child_r)\n", "  File \"/usr/local/lib/python3.10/multiprocessing/process.py\", line 314, in _bootstrap\n    self.run()\n", "  File \"/usr/local/lib/python3.10/multiprocessing/process.py\", line 108, in run\n    self._target(*self._args, **self._kwargs)\n", "  File \"/usr/local/lib/python3.10/site-packages/mage_ai/orchestration/db/process.py\", line 15, in start_session_and_run\n    results = target(*args)\n", "  File \"/usr/local/lib/python3.10/site-packages/mage_ai/server/scheduler_manager.py\", line 53, in run_scheduler\n    LoopTimeTrigger().start()\n", "  File \"/usr/local/lib/python3.10/site-packages/mage_ai/orchestration/triggers/loop_time_trigger.py\", line 14, in start\n    self.run()\n", "  File \"/usr/local/lib/python3.10/site-packages/mage_ai/orchestration/triggers/time_trigger.py\", line 11, in run\n    schedule_all()\n", "  File \"/usr/local/lib/python3.10/site-packages/mage_ai/orchestration/pipeline_scheduler_original.py\", line 1626, in schedule_all\n    PipelineScheduler(r).start()\n", "  File \"/usr/local/lib/python3.10/site-packages/mage_ai/orchestration/db/__init__.py\", line 157, in func_with_rollback\n    return func(*args, **kwargs)\n", "  File \"/usr/local/lib/python3.10/site-packages/mage_ai/orchestration/pipeline_scheduler_original.py\", line 190, in start\n    self.schedule()\n", "  File \"/usr/local/lib/python3.10/site-packages/mage_ai/orchestration/db/__init__.py\", line 157, in func_with_rollback\n    return func(*args, **kwargs)\n", "  File \"/usr/local/lib/python3.10/site-packages/mage_ai/orchestration/pipeline_scheduler_original.py\", line 318, in schedule\n    self.__schedule_blocks(block_runs)\n", "  File \"/usr/local/lib/python3.10/site-packages/mage_ai/orchestration/pipeline_scheduler_original.py\", line 611, in __schedule_blocks\n    job_manager.add_job(\n", "  File \"/usr/local/lib/python3.10/site-packages/mage_ai/orchestration/job_manager.py\", line 28, in add_job\n    self.queue.enqueue(job_id, target, *args, **kwargs)\n", "  File \"/usr/local/lib/python3.10/site-packages/mage_ai/orchestration/queue/process_queue.py\", line 121, in enqueue\n    self.start_worker_pool()\n", "  File \"/usr/local/lib/python3.10/site-packages/mage_ai/orchestration/queue/process_queue.py\", line 198, in start_worker_pool\n    self.worker_pool_proc.start()\n", "  File \"/usr/local/lib/python3.10/multiprocessing/process.py\", line 121, in start\n    self._popen = self._Popen(self)\n", "  File \"/usr/local/lib/python3.10/multiprocessing/context.py\", line 224, in _Popen\n    return _default_context.get_context().Process._Popen(process_obj)\n", "  File \"/usr/local/lib/python3.10/multiprocessing/context.py\", line 281, in _Popen\n    return Popen(process_obj)\n", "  File \"/usr/local/lib/python3.10/multiprocessing/popen_fork.py\", line 19, in __init__\n    self._launch(process_obj)\n", "  File \"/usr/local/lib/python3.10/multiprocessing/popen_fork.py\", line 71, in _launch\n    code = process_obj._bootstrap(parent_sentinel=child_r)\n", "  File \"/usr/local/lib/python3.10/multiprocessing/process.py\", line 314, in _bootstrap\n    self.run()\n", "  File \"/usr/local/lib/python3.10/multiprocessing/process.py\", line 108, in run\n    self._target(*self._args, **self._kwargs)\n", "  File \"/usr/local/lib/python3.10/site-packages/mage_ai/orchestration/queue/process_queue.py\", line 351, in poll_job_and_execute\n    worker.start()\n", "  File \"/usr/local/lib/python3.10/multiprocessing/process.py\", line 121, in start\n    self._popen = self._Popen(self)\n", "  File \"/usr/local/lib/python3.10/multiprocessing/context.py\", line 224, in _Popen\n    return _default_context.get_context().Process._Popen(process_obj)\n", "  File \"/usr/local/lib/python3.10/multiprocessing/context.py\", line 281, in _Popen\n    return Popen(process_obj)\n", "  File \"/usr/local/lib/python3.10/multiprocessing/popen_fork.py\", line 19, in __init__\n    self._launch(process_obj)\n", "  File \"/usr/local/lib/python3.10/multiprocessing/popen_fork.py\", line 71, in _launch\n    code = process_obj._bootstrap(parent_sentinel=child_r)\n", "  File \"/usr/local/lib/python3.10/multiprocessing/process.py\", line 314, in _bootstrap\n    self.run()\n", "  File \"/usr/local/lib/python3.10/site-packages/newrelic/api/background_task.py\", line 117, in wrapper\n    return wrapped(*args, **kwargs)\n", "  File \"/usr/local/lib/python3.10/site-packages/mage_ai/orchestration/queue/process_queue.py\", line 315, in run\n    start_session_and_run(args[1], *args[2], **args[3])\n", "  File \"/usr/local/lib/python3.10/site-packages/mage_ai/orchestration/db/process.py\", line 15, in start_session_and_run\n    results = target(*args)\n", "  File \"/usr/local/lib/python3.10/site-packages/mage_ai/orchestration/pipeline_scheduler_original.py\", line 1163, in run_block\n    return ExecutorFactory.get_block_executor(\n", "  File \"/usr/local/lib/python3.10/site-packages/mage_ai/data_preparation/executors/block_executor.py\", line 613, in execute\n    result = __execute_with_retry()\n", "  File \"/usr/local/lib/python3.10/site-packages/mage_ai/shared/retry.py\", line 46, in retry_func\n    logger.warning(\n", "  File \"/usr/local/lib/python3.10/site-packages/mage_ai/data_preparation/logging/logger.py\", line 39, in warning\n    self.__send_message('warning', message, **kwargs)\n", "  File \"/usr/local/lib/python3.10/site-packages/mage_ai/data_preparation/logging/logger.py\", line 65, in __send_message\n    data['error_stack'] = traceback.format_stack(),\n"]], "error_stacktrace": ["Failed to pass tests for block transform_taxi_data"]}
2024-04-20T07:41:12 {"block_run_id": 86, "block_uuid": "transform_taxi_data", "pipeline_run_id": 27, "pipeline_schedule_id": 2, "pipeline_uuid": "etl_gcs_green_data", "hostname": "54ba8a1e31e8", "block_type": "transformer", "level": "EXCEPTION", "message": "Failed to execute block transform_taxi_data", "timestamp": 1713598872.708483, "uuid": "3f628886fc124e0fa76357c2362eb9ab", "error": ["Traceback (most recent call last):\n  File \"/usr/local/lib/python3.10/site-packages/mage_ai/data_preparation/executors/block_executor.py\", line 613, in execute\n    result = __execute_with_retry()\n  File \"/usr/local/lib/python3.10/site-packages/mage_ai/shared/retry.py\", line 54, in retry_func\n    raise e\n  File \"/usr/local/lib/python3.10/site-packages/mage_ai/shared/retry.py\", line 38, in retry_func\n    return func(*args, **kwargs)\n  File \"/usr/local/lib/python3.10/site-packages/mage_ai/data_preparation/executors/block_executor.py\", line 588, in __execute_with_retry\n    return self._execute(\n  File \"/usr/local/lib/python3.10/site-packages/mage_ai/data_preparation/executors/block_executor.py\", line 1107, in _execute\n    self.block.run_tests(\n  File \"/usr/local/lib/python3.10/site-packages/mage_ai/data_preparation/models/block/__init__.py\", line 2842, in run_tests\n    raise Exception(f'Failed to pass tests for block {self.uuid}')\nException: Failed to pass tests for block transform_taxi_data\n"], "error_stack": [["  File \"/usr/local/bin/mage\", line 8, in <module>\n    sys.exit(app())\n", "  File \"/usr/local/lib/python3.10/site-packages/typer/main.py\", line 311, in __call__\n    return get_command(self)(*args, **kwargs)\n", "  File \"/usr/local/lib/python3.10/site-packages/click/core.py\", line 1130, in __call__\n    return self.main(*args, **kwargs)\n", "  File \"/usr/local/lib/python3.10/site-packages/typer/core.py\", line 778, in main\n    return _main(\n", "  File \"/usr/local/lib/python3.10/site-packages/typer/core.py\", line 216, in _main\n    rv = self.invoke(ctx)\n", "  File \"/usr/local/lib/python3.10/site-packages/click/core.py\", line 1657, in invoke\n    return _process_result(sub_ctx.command.invoke(sub_ctx))\n", "  File \"/usr/local/lib/python3.10/site-packages/click/core.py\", line 1404, in invoke\n    return ctx.invoke(self.callback, **ctx.params)\n", "  File \"/usr/local/lib/python3.10/site-packages/click/core.py\", line 760, in invoke\n    return __callback(*args, **kwargs)\n", "  File \"/usr/local/lib/python3.10/site-packages/typer/main.py\", line 683, in wrapper\n    return callback(**use_params)  # type: ignore\n", "  File \"/usr/local/lib/python3.10/site-packages/mage_ai/cli/main.py\", line 163, in start\n    start_server(\n", "  File \"/usr/local/lib/python3.10/site-packages/mage_ai/server/server.py\", line 750, in start_server\n    scheduler_manager.start_scheduler()\n", "  File \"/usr/local/lib/python3.10/site-packages/mage_ai/server/scheduler_manager.py\", line 92, in start_scheduler\n    proc.start()\n", "  File \"/usr/local/lib/python3.10/multiprocessing/process.py\", line 121, in start\n    self._popen = self._Popen(self)\n", "  File \"/usr/local/lib/python3.10/multiprocessing/context.py\", line 224, in _Popen\n    return _default_context.get_context().Process._Popen(process_obj)\n", "  File \"/usr/local/lib/python3.10/multiprocessing/context.py\", line 281, in _Popen\n    return Popen(process_obj)\n", "  File \"/usr/local/lib/python3.10/multiprocessing/popen_fork.py\", line 19, in __init__\n    self._launch(process_obj)\n", "  File \"/usr/local/lib/python3.10/multiprocessing/popen_fork.py\", line 71, in _launch\n    code = process_obj._bootstrap(parent_sentinel=child_r)\n", "  File \"/usr/local/lib/python3.10/multiprocessing/process.py\", line 314, in _bootstrap\n    self.run()\n", "  File \"/usr/local/lib/python3.10/multiprocessing/process.py\", line 108, in run\n    self._target(*self._args, **self._kwargs)\n", "  File \"/usr/local/lib/python3.10/site-packages/mage_ai/orchestration/db/process.py\", line 15, in start_session_and_run\n    results = target(*args)\n", "  File \"/usr/local/lib/python3.10/site-packages/mage_ai/server/scheduler_manager.py\", line 53, in run_scheduler\n    LoopTimeTrigger().start()\n", "  File \"/usr/local/lib/python3.10/site-packages/mage_ai/orchestration/triggers/loop_time_trigger.py\", line 14, in start\n    self.run()\n", "  File \"/usr/local/lib/python3.10/site-packages/mage_ai/orchestration/triggers/time_trigger.py\", line 11, in run\n    schedule_all()\n", "  File \"/usr/local/lib/python3.10/site-packages/mage_ai/orchestration/pipeline_scheduler_original.py\", line 1626, in schedule_all\n    PipelineScheduler(r).start()\n", "  File \"/usr/local/lib/python3.10/site-packages/mage_ai/orchestration/db/__init__.py\", line 157, in func_with_rollback\n    return func(*args, **kwargs)\n", "  File \"/usr/local/lib/python3.10/site-packages/mage_ai/orchestration/pipeline_scheduler_original.py\", line 190, in start\n    self.schedule()\n", "  File \"/usr/local/lib/python3.10/site-packages/mage_ai/orchestration/db/__init__.py\", line 157, in func_with_rollback\n    return func(*args, **kwargs)\n", "  File \"/usr/local/lib/python3.10/site-packages/mage_ai/orchestration/pipeline_scheduler_original.py\", line 318, in schedule\n    self.__schedule_blocks(block_runs)\n", "  File \"/usr/local/lib/python3.10/site-packages/mage_ai/orchestration/pipeline_scheduler_original.py\", line 611, in __schedule_blocks\n    job_manager.add_job(\n", "  File \"/usr/local/lib/python3.10/site-packages/mage_ai/orchestration/job_manager.py\", line 28, in add_job\n    self.queue.enqueue(job_id, target, *args, **kwargs)\n", "  File \"/usr/local/lib/python3.10/site-packages/mage_ai/orchestration/queue/process_queue.py\", line 121, in enqueue\n    self.start_worker_pool()\n", "  File \"/usr/local/lib/python3.10/site-packages/mage_ai/orchestration/queue/process_queue.py\", line 198, in start_worker_pool\n    self.worker_pool_proc.start()\n", "  File \"/usr/local/lib/python3.10/multiprocessing/process.py\", line 121, in start\n    self._popen = self._Popen(self)\n", "  File \"/usr/local/lib/python3.10/multiprocessing/context.py\", line 224, in _Popen\n    return _default_context.get_context().Process._Popen(process_obj)\n", "  File \"/usr/local/lib/python3.10/multiprocessing/context.py\", line 281, in _Popen\n    return Popen(process_obj)\n", "  File \"/usr/local/lib/python3.10/multiprocessing/popen_fork.py\", line 19, in __init__\n    self._launch(process_obj)\n", "  File \"/usr/local/lib/python3.10/multiprocessing/popen_fork.py\", line 71, in _launch\n    code = process_obj._bootstrap(parent_sentinel=child_r)\n", "  File \"/usr/local/lib/python3.10/multiprocessing/process.py\", line 314, in _bootstrap\n    self.run()\n", "  File \"/usr/local/lib/python3.10/multiprocessing/process.py\", line 108, in run\n    self._target(*self._args, **self._kwargs)\n", "  File \"/usr/local/lib/python3.10/site-packages/mage_ai/orchestration/queue/process_queue.py\", line 351, in poll_job_and_execute\n    worker.start()\n", "  File \"/usr/local/lib/python3.10/multiprocessing/process.py\", line 121, in start\n    self._popen = self._Popen(self)\n", "  File \"/usr/local/lib/python3.10/multiprocessing/context.py\", line 224, in _Popen\n    return _default_context.get_context().Process._Popen(process_obj)\n", "  File \"/usr/local/lib/python3.10/multiprocessing/context.py\", line 281, in _Popen\n    return Popen(process_obj)\n", "  File \"/usr/local/lib/python3.10/multiprocessing/popen_fork.py\", line 19, in __init__\n    self._launch(process_obj)\n", "  File \"/usr/local/lib/python3.10/multiprocessing/popen_fork.py\", line 71, in _launch\n    code = process_obj._bootstrap(parent_sentinel=child_r)\n", "  File \"/usr/local/lib/python3.10/multiprocessing/process.py\", line 314, in _bootstrap\n    self.run()\n", "  File \"/usr/local/lib/python3.10/site-packages/newrelic/api/background_task.py\", line 117, in wrapper\n    return wrapped(*args, **kwargs)\n", "  File \"/usr/local/lib/python3.10/site-packages/mage_ai/orchestration/queue/process_queue.py\", line 315, in run\n    start_session_and_run(args[1], *args[2], **args[3])\n", "  File \"/usr/local/lib/python3.10/site-packages/mage_ai/orchestration/db/process.py\", line 15, in start_session_and_run\n    results = target(*args)\n", "  File \"/usr/local/lib/python3.10/site-packages/mage_ai/orchestration/pipeline_scheduler_original.py\", line 1163, in run_block\n    return ExecutorFactory.get_block_executor(\n", "  File \"/usr/local/lib/python3.10/site-packages/mage_ai/data_preparation/executors/block_executor.py\", line 615, in execute\n    self.logger.exception(\n", "  File \"/usr/local/lib/python3.10/site-packages/mage_ai/data_preparation/logging/logger.py\", line 30, in exception\n    self.__send_message('exception', message, **kwargs)\n", "  File \"/usr/local/lib/python3.10/site-packages/mage_ai/data_preparation/logging/logger.py\", line 65, in __send_message\n    data['error_stack'] = traceback.format_stack(),\n"]], "error_stacktrace": ["Failed to pass tests for block transform_taxi_data"]}
Traceback (most recent call last):
  File "/usr/local/lib/python3.10/site-packages/mage_ai/data_preparation/executors/block_executor.py", line 613, in execute
    result = __execute_with_retry()
  File "/usr/local/lib/python3.10/site-packages/mage_ai/shared/retry.py", line 54, in retry_func
    raise e
  File "/usr/local/lib/python3.10/site-packages/mage_ai/shared/retry.py", line 38, in retry_func
    return func(*args, **kwargs)
  File "/usr/local/lib/python3.10/site-packages/mage_ai/data_preparation/executors/block_executor.py", line 588, in __execute_with_retry
    return self._execute(
  File "/usr/local/lib/python3.10/site-packages/mage_ai/data_preparation/executors/block_executor.py", line 1107, in _execute
    self.block.run_tests(
  File "/usr/local/lib/python3.10/site-packages/mage_ai/data_preparation/models/block/__init__.py", line 2842, in run_tests
    raise Exception(f'Failed to pass tests for block {self.uuid}')
Exception: Failed to pass tests for block transform_taxi_data
2024-04-20T07:42:39 {"block_run_id": 125, "block_uuid": "transform_taxi_data", "pipeline_run_id": 40, "pipeline_schedule_id": 2, "pipeline_uuid": "etl_gcs_green_data", "hostname": "54ba8a1e31e8", "block_type": "transformer", "level": "INFO", "message": "Start executing block with BlockExecutor.", "timestamp": 1713598959.05562, "uuid": "88f4463b10174399bea5434a0a88f795"}
2024-04-20T07:42:39 {"block_run_id": 125, "block_uuid": "transform_taxi_data", "pipeline_run_id": 40, "pipeline_schedule_id": 2, "pipeline_uuid": "etl_gcs_green_data", "hostname": "54ba8a1e31e8", "block_type": "transformer", "level": "INFO", "message": "Preprocessing: rows with zero passengers 161", "timestamp": 1713598959.454657, "uuid": "e3cd267a684b4fda9a316d48f8a60a16"}
2024-04-20T07:42:40 {"block_run_id": 125, "block_uuid": "transform_taxi_data", "pipeline_run_id": 40, "pipeline_schedule_id": 2, "pipeline_uuid": "etl_gcs_green_data", "hostname": "54ba8a1e31e8", "block_type": "transformer", "level": "INFO", "message": "--------------------------------------------------------------", "timestamp": 1713598960.466212, "uuid": "ec51ea68e02f4014b237e218583daa9e"}
2024-04-20T07:42:40 {"block_run_id": 125, "block_uuid": "transform_taxi_data", "pipeline_run_id": 40, "pipeline_schedule_id": 2, "pipeline_uuid": "etl_gcs_green_data", "hostname": "54ba8a1e31e8", "block_type": "transformer", "level": "INFO", "message": "1/1 tests passed.", "timestamp": 1713598960.468376, "uuid": "10e8c86c45464c0681130617462e5d71"}
2024-04-20T07:42:40 {"block_run_id": 125, "block_uuid": "transform_taxi_data", "pipeline_run_id": 40, "pipeline_schedule_id": 2, "pipeline_uuid": "etl_gcs_green_data", "hostname": "54ba8a1e31e8", "block_type": "transformer", "level": "INFO", "message": "Finish executing block with BlockExecutor.", "timestamp": 1713598960.472366, "uuid": "7c6ba8ab909b4899b1e4f40dc98df071"}
